<?xml version="1.0" encoding="utf-8"?>
<!-- This URDF was automatically created by SolidWorks to URDF Exporter! Originally created by Stephen Brawner (brawner@gmail.com) 
     Commit Version:   Build Version: 1.6.8803.23649
     For more information, please see http://wiki.ros.org/sw_urdf_exporter -->
<robot
  name="osam_arm_4_urdf_v2">

  <link name="world"/>

  <joint name="base_joint" type="fixed">
    <parent link="world"/>
    <child link="base_link"/>
    <origin rpy="0 0 0" xyz="0.0 0.0 6.0"/>
  </joint>
 
  <link
    name="base_link">
    <inertial>
      <origin
        xyz="6.991E-06 0.018435 0.00015935"
        rpy="0 0 0" />
      <mass
        value="0.01" />
      <inertia
        ixx="0.002"
        ixy="0.0"
        ixz="0.0"
        iyy="0.02"
        iyz="0.0"
        izz="0.002" />
    </inertial>
    <visual>
      <origin
        xyz="0 0 0"
        rpy="0 0 0" />
      <geometry>
        <mesh
          filename="package://osam_arm_4_urdf_v2/meshes/base_link.STL" />
      </geometry>
      <material
        name="">
        <color
          rgba="0.79216 0.81961 0.93333 1" />
      </material>
    </visual>
    <collision>
      <origin
        xyz="0 0 0"
        rpy="0 0 0" />
      <geometry>
        <mesh
          filename="package://osam_arm_4_urdf_v2/meshes/base_link.STL" />
      </geometry>
    </collision>
  </link>
  <link
    name="link_1">
    <inertial>
      <origin
        xyz="2.5674E-06 0.090696 -0.076696"
        rpy="0 0 0" />
      <mass
        value="0.01" />
      <inertia
        ixx="0.002"
        ixy="0.0"
        ixz="0.0"
        iyy="0.02"
        iyz="0.0"
        izz="0.002" />
    </inertial>
    <visual>
      <origin
        xyz="0 0 0"
        rpy="0 0 0" />
      <geometry>
        <mesh
          filename="package://osam_arm_4_urdf_v2/meshes/link_1.STL" />
      </geometry>
      <material
        name="">
        <color
          rgba="0.79216 0.81961 0.93333 1" />
      </material>
    </visual>
    <collision>
      <origin
        xyz="0 0 0"
        rpy="0 0 0" />
      <geometry>
        <mesh
          filename="package://osam_arm_4_urdf_v2/meshes/link_1.STL" />
      </geometry>
    </collision>
  </link>
  <joint
    name="joint0"
    type="revolute">
    <origin
      xyz="0 0 0.030189"
      rpy="1.5708 0 0" />
    <parent
      link="base_link" />
    <child
      link="link_1" />
    <axis
      xyz="0 1 0" />
    <limit
      lower="-3.14"
      upper="3.14"
      effort="111"
      velocity="3" />
  </joint>
  <link
    name="link_2">
    <inertial>
      <origin
        xyz="-3.362E-06 0.091219 -0.083339"
        rpy="0 0 0" />
      <mass
        value="0.01" />
      <inertia
        ixx="0.002"
        ixy="0.0"
        ixz="0.0"
        iyy="0.02"
        iyz="0.0"
        izz="0.002" />
    </inertial>
    <visual>
      <origin
        xyz="0 0 0"
        rpy="0 0 0" />
      <geometry>
        <mesh
          filename="package://osam_arm_4_urdf_v2/meshes/link_2.STL" />
      </geometry>
      <material
        name="">
        <color
          rgba="0.79216 0.81961 0.93333 1" />
      </material>
    </visual>
    <collision>
      <origin
        xyz="0 0 0"
        rpy="0 0 0" />
      <geometry>
        <mesh
          filename="package://osam_arm_4_urdf_v2/meshes/link_2.STL" />
      </geometry>
    </collision>
  </link>
  <joint
    name="joint1"
    type="revolute">
    <origin
      xyz="0 0.097811 -0.2784"
      rpy="0 0 0" />
    <parent
      link="link_1" />
    <child
      link="link_2" />
    <axis
      xyz="0 0 1" />
    <limit
      lower="-3.14"
      upper="3.14"
      effort="111"
      velocity="3" />
  </joint>
  <link
    name="link_3">
    <inertial>
      <origin
        xyz="-1.1715E-06 -1.0393 -0.089088"
        rpy="0 0 0" />
      <mass
        value="0.01" />
      <inertia
        ixx="0.002"
        ixy="0.0"
        ixz="0.0"
        iyy="0.02"
        iyz="0.0"
        izz="0.002" />
    </inertial>
    <visual>
      <origin
        xyz="0 0 0"
        rpy="0 0 0" />
      <geometry>
        <mesh
          filename="package://osam_arm_4_urdf_v2/meshes/link_3.STL" />
      </geometry>
      <material
        name="">
        <color
          rgba="0.79216 0.81961 0.93333 1" />
      </material>
    </visual>
    <collision>
      <origin
        xyz="0 0 0"
        rpy="0 0 0" />
      <geometry>
        <mesh
          filename="package://osam_arm_4_urdf_v2/meshes/link_3.STL" />
      </geometry>
    </collision>
  </link>
  <joint
    name="joint2"
    type="revolute">
    <origin
      xyz="0 0.3154 -0.09"
      rpy="1.5708 0 0" />
    <parent
      link="link_2" />
    <child
      link="link_3" />
    <axis
      xyz="0 0 1" />
    <limit
      lower="-3.14"
      upper="3.14"
      effort="111"
      velocity="3" />
  </joint>
  <link
    name="link_4">
    <inertial>
      <origin
        xyz="5.3111E-08 1.0616 0.073084"
        rpy="0 0 0" />
      <mass
        value="0.01" />
      <inertia
        ixx="0.002"
        ixy="0.0"
        ixz="0.0"
        iyy="0.02"
        iyz="0.0"
        izz="0.002" />
    </inertial>
    <visual>
      <origin
        xyz="0 0 0"
        rpy="0 0 0" />
      <geometry>
        <mesh
          filename="package://osam_arm_4_urdf_v2/meshes/link_4.STL" />
      </geometry>
      <material
        name="">
        <color
          rgba="0.79216 0.81961 0.93333 1" />
      </material>
    </visual>
    <collision>
      <origin
        xyz="0 0 0"
        rpy="0 0 0" />
      <geometry>
        <mesh
          filename="package://osam_arm_4_urdf_v2/meshes/link_4.STL" />
      </geometry>
    </collision>
  </link>
  <joint
    name="joint3"
    type="revolute">
    <origin
      xyz="0 -2.2307 -0.14467"
      rpy="3.1416 0 0" />
    <parent
      link="link_3" />
    <child
      link="link_4" />
    <axis
      xyz="0 0 1" />
    <limit
      lower="-3.14"
      upper="3.14"
      effort="111"
      velocity="3" />
  </joint>
  <link
    name="link_5">
    <inertial>
      <origin
        xyz="1.2326E-06 0.0034231 -0.17222"
        rpy="0 0 0" />
      <mass
        value="0.01" />
      <inertia
        ixx="0.002"
        ixy="0.0"
        ixz="0.0"
        iyy="0.02"
        iyz="0.0"
        izz="0.002" />
    </inertial>
    <visual>
      <origin
        xyz="0 0 0"
        rpy="0 0 0" />
      <geometry>
        <mesh
          filename="package://osam_arm_4_urdf_v2/meshes/link_5.STL" />
      </geometry>
      <material
        name="">
        <color
          rgba="0.79216 0.81961 0.93333 1" />
      </material>
    </visual>
    <collision>
      <origin
        xyz="0 0 0"
        rpy="0 0 0" />
      <geometry>
        <mesh
          filename="package://osam_arm_4_urdf_v2/meshes/link_5.STL" />
      </geometry>
    </collision>
  </link>
  <joint
    name="joint4"
    type="revolute">
    <origin
      xyz="0 2.1987 0.13404"
      rpy="3.1416 0 -3.1416" />
    <parent
      link="link_4" />
    <child
      link="link_5" />
    <axis
      xyz="0 0 1" />
    <limit
      lower="-3.14"
      upper="3.14"
      effort="111"
      velocity="3" />
  </joint>
  <link
    name="link_6">
    <inertial>
      <origin
        xyz="-1.5252E-06 0.15302 -0.0038197"
        rpy="0 0 0" />
      <mass
        value="0.01" />
      <inertia
        ixx="0.002"
        ixy="0.0"
        ixz="0.0"
        iyy="0.02"
        iyz="0.0"
        izz="0.002" />
    </inertial>
    <visual>
      <origin
        xyz="0 0 0"
        rpy="0 0 0" />
      <geometry>
        <mesh
          filename="package://osam_arm_4_urdf_v2/meshes/link_6.STL" />
      </geometry>
      <material
        name="">
        <color
          rgba="0.79216 0.81961 0.93333 1" />
      </material>
    </visual>
    <collision>
      <origin
        xyz="0 0 0"
        rpy="0 0 0" />
      <geometry>
        <mesh
          filename="package://osam_arm_4_urdf_v2/meshes/link_6.STL" />
      </geometry>
    </collision>
  </link>
  <joint
    name="joint5"
    type="revolute">
    <origin
      xyz="0 0.060895 -0.28421"
      rpy="3.1416 0 -3.1416" />
    <parent
      link="link_5" />
    <child
      link="link_6" />
    <axis
      xyz="0 1 0" />
    <limit
      lower="-3.14"
      upper="3.14"
      effort="111"
      velocity="3" />
  </joint>
  <link
    name="ee_link">
    <inertial>
      <origin
        xyz="-2.9345E-09 0.022658 1.3952E-07"
        rpy="0 0 0" />
      <mass
        value="0.01" />
      <inertia
        ixx="0.002"
        ixy="0.0"
        ixz="0.0"
        iyy="0.02"
        iyz="0.0"
        izz="0.002" />
    </inertial>
    <visual>
      <origin
        xyz="0 0 0"
        rpy="0 0 0" />
      <geometry>
        <mesh
          filename="package://osam_arm_4_urdf_v2/meshes/link_7.STL" />
      </geometry>
      <material
        name="">
        <color
          rgba="0.79216 0.81961 0.93333 1" />
      </material>
    </visual>
    <collision>
      <origin
        xyz="0 0 0"
        rpy="0 0 0" />
      <geometry>
        <mesh
          filename="package://osam_arm_4_urdf_v2/meshes/link_7.STL" />
      </geometry>
    </collision>
  </link>
  <joint
    name="joint6"
    type="revolute">
    <origin
      xyz="0 0.24721 -0.0617"
      rpy="-1.5708 0 0" />
    <parent
      link="link_6" />
    <child
      link="ee_link" />
    <axis
      xyz="0 1 0" />
    <limit
      lower="-3.14"
      upper="3.14"
      effort="111"
      velocity="3" />
  </joint>
  <link
    name="link_8">
    <inertial>
      <origin
        xyz="-0.087027 0.022495 0"
        rpy="0 0 0" />
      <mass
        value="0.01" />
      <inertia
        ixx="0.002"
        ixy="0.0"
        ixz="0.0"
        iyy="0.02"
        iyz="0.0"
        izz="0.002" />
    </inertial>
    <visual>
      <origin
        xyz="0 0 0"
        rpy="0 0 0" />
      <geometry>
        <mesh
          filename="package://osam_arm_4_urdf_v2/meshes/link_8.STL" />
      </geometry>
      <material
        name="">
        <color
          rgba="0.79216 0.81961 0.93333 1" />
      </material>
    </visual>
    <collision>
      <origin
        xyz="0 0 0"
        rpy="0 0 0" />
      <geometry>
        <mesh
          filename="package://osam_arm_4_urdf_v2/meshes/link_8.STL" />
      </geometry>
    </collision>
  </link>
  <joint
    name="joint7"
    type="prismatic">
    <origin
      xyz="0 0.05 0"
      rpy="0 0 0" />
    <parent
      link="ee_link" />
    <child
      link="link_8" />
    <axis
      xyz="1 0 0" />
    <limit
      lower="0"
      upper="0.04"
      effort="111"
      velocity="3" />
  </joint>
  <link
    name="link_9">
    <inertial>
      <origin
        xyz="-0.16203 0.00049522 -0.03"
        rpy="0 0 0" />
      <mass
        value="0.01" />
      <inertia
        ixx="0.002"
        ixy="0.0"
        ixz="0.0"
        iyy="0.02"
        iyz="0.0"
        izz="0.002" />
    </inertial>
    <visual>
      <origin
        xyz="0 0 0"
        rpy="0 0 0" />
      <geometry>
        <mesh
          filename="package://osam_arm_4_urdf_v2/meshes/link_9.STL" />
      </geometry>
      <material
        name="">
        <color
          rgba="0.79216 0.81961 0.93333 1" />
      </material>
    </visual>
    <collision>
      <origin
        xyz="0 0 0"
        rpy="0 0 0" />
      <geometry>
        <mesh
          filename="package://osam_arm_4_urdf_v2/meshes/link_9.STL" />
      </geometry>
    </collision>
  </link>
  <joint
    name="joint8"
    type="prismatic">
    <origin
      xyz="-0.075 0.072 -0.03"
      rpy="3.1416 0 3.1416" />
    <parent
      link="ee_link" />
    <child
      link="link_9" />
    <axis
      xyz="1 0 0" />
    <limit
      lower="-0.04"
      upper="0"
      effort="111"
      velocity="3" />
  </joint>

  <transmission name="link_1_trans">
    <type>transmission_interface/SimpleTransmission</type>

    <joint name="joint0">
      <hardwareInterface>hardware_interface/PositionJointInterface</hardwareInterface>
    </joint>

    <actuator name="link_1_motor">
      <hardwareInterface>hardware_interface/PositionJointInterface</hardwareInterface> 
      <mechanicalReduction>1</mechanicalReduction>
    </actuator>
  </transmission>

  <transmission name="link_2_trans">
    <type>transmission_interface/SimpleTransmission</type>

    <joint name="joint1">
      <hardwareInterface>hardware_interface/PositionJointInterface</hardwareInterface>
    </joint>

    <actuator name="link_2_motor">
      <hardwareInterface>hardware_interface/PositionJointInterface</hardwareInterface> 
      <mechanicalReduction>1</mechanicalReduction>
    </actuator>
  </transmission>

  <transmission name="link_3_trans">
    <type>transmission_interface/SimpleTransmission</type>

    <joint name="joint2">
      <hardwareInterface>hardware_interface/PositionJointInterface</hardwareInterface>
    </joint>

    <actuator name="link_3_motor">
      <hardwareInterface>hardware_interface/PositionJointInterface</hardwareInterface> 
      <mechanicalReduction>1</mechanicalReduction>
    </actuator>
  </transmission>

  <transmission name="link_4_trans">
    <type>transmission_interface/SimpleTransmission</type>

    <joint name="joint3">
      <hardwareInterface>hardware_interface/PositionJointInterface</hardwareInterface>
    </joint>

    <actuator name="link_4_motor">
      <hardwareInterface>hardware_interface/PositionJointInterface</hardwareInterface> 
      <mechanicalReduction>1</mechanicalReduction>
    </actuator>
  </transmission>

  <transmission name="link_5_trans">
    <type>transmission_interface/SimpleTransmission</type>

    <joint name="joint4">
      <hardwareInterface>hardware_interface/PositionJointInterface</hardwareInterface>
    </joint>

    <actuator name="link_5_motor">
      <hardwareInterface>hardware_interface/PositionJointInterface</hardwareInterface> 
      <mechanicalReduction>1</mechanicalReduction>
    </actuator>
  </transmission>

  <transmission name="link_6_trans">
    <type>transmission_interface/SimpleTransmission</type>

    <joint name="joint5">
      <hardwareInterface>hardware_interface/PositionJointInterface</hardwareInterface>
    </joint>

    <actuator name="link_6_motor">
      <hardwareInterface>hardware_interface/PositionJointInterface</hardwareInterface> 
      <mechanicalReduction>1</mechanicalReduction>
    </actuator>
  </transmission>

  <transmission name="ee_link_trans">
    <type>transmission_interface/SimpleTransmission</type>

    <joint name="joint6">
      <hardwareInterface>hardware_interface/PositionJointInterface</hardwareInterface>
    </joint>

    <actuator name="ee_link_motor">
      <hardwareInterface>hardware_interface/PositionJointInterface</hardwareInterface> 
      <mechanicalReduction>1</mechanicalReduction>
    </actuator>
  </transmission>

  <transmission name="link_8_trans">
    <type>transmission_interface/SimpleTransmission</type>

    <joint name="joint7">
      <hardwareInterface>hardware_interface/PositionJointInterface</hardwareInterface>
    </joint>

    <actuator name="link_8_motor">
      <hardwareInterface>hardware_interface/PositionJointInterface</hardwareInterface> 
      <mechanicalReduction>1</mechanicalReduction>
    </actuator>
  </transmission>

  <transmission name="link_9_trans">
    <type>transmission_interface/SimpleTransmission</type>

    <joint name="joint8">
      <hardwareInterface>hardware_interface/PositionJointInterface</hardwareInterface>
    </joint>

    <actuator name="link_9_motor">
      <hardwareInterface>hardware_interface/PositionJointInterface</hardwareInterface> 
      <mechanicalReduction>1</mechanicalReduction>
    </actuator>
  </transmission>

  <gazebo>
    <plugin name="control" filename="libgazebo_ros_control.so">
      <robotNamespace>/</robotNamespace>
    </plugin>
  </gazebo>

  <gazebo reference="link_1">
    <selfCollide>true</selfCollide>
  </gazebo>

  <gazebo reference="link_2">
    <selfCollide>true</selfCollide>
  </gazebo>

  <gazebo reference="link_3">
    <selfCollide>true</selfCollide>
  </gazebo>

  <gazebo reference="link_4">
    <selfCollide>true</selfCollide>
  </gazebo>

  <gazebo reference="link_5">
    <selfCollide>true</selfCollide>
  </gazebo>

  <gazebo reference="link_6">
    <selfCollide>true</selfCollide>
  </gazebo>

  <gazebo reference="ee_link">
    <selfCollide>true</selfCollide>
  </gazebo>

  <gazebo reference="link_8">
    <selfCollide>true</selfCollide>
  </gazebo>

  <gazebo reference="link_9">
    <selfCollide>true</selfCollide>
  </gazebo>



</robot>